<?xml version="1.0" ?>
<sdf version="1.5">
  <model name="JVRC_R3A_obj">

    <link name="R3A_door">
      <pose>0 0 0.1 0 0 0</pose>
      <inertial>
        <mass>20</mass>
        <pose> 4.251915 10.395275 0.886111 0 0 0</pose>
        <inertia>
          <ixx> 0.2383020</ixx>
          <ixy>-1.6486429</ixy>
          <ixz>-0.0005112</ixz>
          <iyy> 0.1212531</iyy>
          <iyz>-0.0211655</iyz>
          <izz> 0.3571020</izz>
        </inertia>
      </inertial>
      <visual name="visual">
        <geometry>
          <mesh>
            <uri>model://JVRC_R3A_obj/dae/R3A_door0.7.dae</uri>
          </mesh>
        </geometry>
      </visual>
      <collision name="collision">
        <geometry>
          <mesh>
            <uri>model://JVRC_R3A_obj/dae/R3A_door0.7.dae</uri>
          </mesh>
        </geometry>
        <surface>
          <friction>
            <ode>
              <mu>0.7</mu>
              <mu2>0.7</mu2>
            </ode>
          </friction>
        </surface>
      </collision>
      <self_collide>1</self_collide>
      <gravity>0</gravity>
    </link>

    <link name="R3A_spreader">
      <pose> -0.2 3.5 0.01 0 0 0 </pose>
      <inertial>
        <mass>14.3</mass>
        <pose>2.263002 1.840704 1.241542 0 0 0</pose>
        <inertia>
          <ixx>0.000261</ixx>
          <ixy>0.000000</ixy>
          <ixz>0.000000</ixz>
          <iyy>0.000035</iyy>
          <iyz>0.000022</iyz>
          <izz>0.000253</izz>
        </inertia>
      </inertial>
      <visual name="visual">
        <geometry>
          <mesh>
            <uri>model://JVRC_R3A_obj/dae/R3A_spreader.dae</uri>
          </mesh>
        </geometry>
      </visual>
      <collision name="collision">
        <geometry>
          <mesh>
            <uri>model://JVRC_R3A_obj/dae/R3A_spreader.dae</uri>
          </mesh>
        </geometry>
        <surface>
					<!--
          <bounce>
            <restitution_coefficient>0.5</restitution_coefficient>
            <threshold>1000000000.0</threshold>
          </bounce>
					-->
          <friction>
            <ode>
              <mu>10</mu>
              <mu2>10</mu2>
            </ode>
          </friction>
        </surface>
      </collision>
      <self_collide>1</self_collide>
      <gravity>1</gravity>
    </link>

    <joint name="hinge_car_door" type="revolute">
      <parent>world</parent>
      <child>R3A_door</child>
      <pose>4.321 10.961 1.0897 0 0 0</pose>
      <axis>
        <xyz>0.02 0.1 0.44</xyz>
        <limit>
          <lower>0</lower>
          <upper>1.5</upper>
        </limit>
        <dynamics>
          <damping>1.0</damping>
          <friction>10.315</friction>
        </dynamics>
      </axis>
      <physics>
        <ode>
          <cfm_damping>1</cfm_damping>
        </ode>
      </physics>
    </joint>

<!--
    <joint name="hinge_surface_door" type="revolute">
      <parent>R3A_surface</parent>
      <child>R3A_door</child>
      <pose>4.2578 10.925 0.797543 0 0 0</pose>
      <axis>
        <xyz>0.02 0.1 0.44</xyz>
      </axis>
    </joint>
-->

  </model>
</sdf>
